Traceback (most recent call last):
  File "/home/hz466/calendar-planning/source/../output/SMT/Llama-3.1-70B-Instruct/calendar/code/calendar_scheduling_example_662.py", line 43, in <module>
    start_time < busy_intervals[person][interval][0], 
    ^^^^^^^^^^^^^^^^^^^^^^^^^^^^^^^^^^^^^^^^^^^^^^^^
  File "/home/hz466/env/lib/python3.12/site-packages/z3/z3.py", line 2707, in __lt__
    a, b = _coerce_exprs(self, other)
           ^^^^^^^^^^^^^^^^^^^^^^^^^^
  File "/home/hz466/env/lib/python3.12/site-packages/z3/z3.py", line 1252, in _coerce_exprs
    b = s.cast(b)
        ^^^^^^^^^
  File "/home/hz466/env/lib/python3.12/site-packages/z3/z3.py", line 2428, in cast
    return IntVal(val, self.ctx)
           ^^^^^^^^^^^^^^^^^^^^^
  File "/home/hz466/env/lib/python3.12/site-packages/z3/z3.py", line 3271, in IntVal
    return IntNumRef(Z3_mk_numeral(ctx.ref(), _to_int_str(val), IntSort(ctx).ast), ctx)
                     ^^^^^^^^^^^^^^^^^^^^^^^^^^^^^^^^^^^^^^^^^^^^^^^^^^^^^^^^^^^^
  File "/home/hz466/env/lib/python3.12/site-packages/z3/z3core.py", line 2387, in Z3_mk_numeral
    _elems.Check(a0)
  File "/home/hz466/env/lib/python3.12/site-packages/z3/z3core.py", line 1575, in Check
    raise self.Exception(self.get_error_message(ctx, err))
z3.z3types.Z3Exception: b'parser error'
