{
    "has_execution_error": true,
    "execution_output": "Traceback (most recent call last):\n  File \"/Users/laiqimei/Desktop/Academic/UPenn/CCB Lab/Project/calendar-planning/source/../output/SMT/DeepSeek-V3/trip/n_pass/trip_planning_example_813/5_pass/solution.py\", line 94, in <module>\n    print(json.dumps(solve_itinerary(), indent=2))\n                     ~~~~~~~~~~~~~~~^^\n  File \"/Users/laiqimei/Desktop/Academic/UPenn/CCB Lab/Project/calendar-planning/source/../output/SMT/DeepSeek-V3/trip/n_pass/trip_planning_example_813/5_pass/solution.py\", line 81, in solve_itinerary\n    solver.pop()\n    ~~~~~~~~~~^^\n  File \"/opt/homebrew/lib/python3.13/site-packages/z3/z3.py\", line 7099, in pop\n    Z3_solver_pop(self.ctx.ref(), self.solver, num)\n    ~~~~~~~~~~~~~^^^^^^^^^^^^^^^^^^^^^^^^^^^^^^^^^^\n  File \"/opt/homebrew/lib/python3.13/site-packages/z3/z3core.py\", line 4183, in Z3_solver_pop\n    _elems.Check(a0)\n    ~~~~~~~~~~~~^^^^\n  File \"/opt/homebrew/lib/python3.13/site-packages/z3/z3core.py\", line 1579, in Check\n    raise self.Exception(self.get_error_message(ctx, err))\nz3.z3types.Z3Exception: b'index out of bounds'\n",
    "pred": {
        "error": "z3.z3types.Z3Exception: b'index out of bounds'"
    },
    "gold": {
        "itinerary": [
            {
                "day_range": "Day 1-3",
                "place": "Vilnius"
            },
            {
                "day_range": "Day 3-7",
                "place": "Frankfurt"
            },
            {
                "day_range": "Day 7-9",
                "place": "Stuttgart"
            },
            {
                "day_range": "Day 9-10",
                "place": "London"
            },
            {
                "day_range": "Day 10-11",
                "place": "Santorini"
            },
            {
                "day_range": "Day 11-13",
                "place": "Dublin"
            },
            {
                "day_range": "Day 13-17",
                "place": "Seville"
            }
        ]
    },
    "status": "Execution error: z3.z3types.Z3Exception: b'index out of bounds'",
    "violated_constraint": {},
    "is_exact_match": false,
    "constraints_satisfied": false,
    "pass_number": 5
}